<?xml version="1.0" ?>
<!-- =================================================================================== -->
<!-- |    This document was autogenerated by xacro from /home/michael/arctos_ros2_ws/src/arctos_description/urdf/arctos.urdf.xacro | -->
<!-- |    EDITING THIS FILE BY HAND IS NOT RECOMMENDED                                 | -->
<!-- =================================================================================== -->
<!-- Entry point: include this file to get full Arctos robot description -->
<robot name="arctos">
  <!-- Standard material definitions reused by all Arctos sub-assemblies -->
  <material name="white">
    <color rgba="1 1 1 1"/>
  </material>
  <material name="black">
    <color rgba="0 0 0 1"/>
  </material>
  <!-- Base and arm link geometries -->
  <link name="base_link">
    <visual>
      <origin rpy="0 0 0" xyz="0 0 0"/>
      <geometry>
        <mesh filename="package://arctos_description/meshes/base_link.stl" scale="0.001 0.001 0.001"/>
      </geometry>
      <material name="white"/>
    </visual>
    <collision>
      <origin rpy="0 0 0" xyz="0 0 0"/>
      <geometry>
        <mesh filename="package://arctos_description/meshes/base_link.stl" scale="0.001 0.001 0.001"/>
      </geometry>
    </collision>
    <inertial>
      <origin rpy="0 0 0" xyz="0.0009375030874740357 0.047087016508753216 0.06663230338123677"/>
      <mass value="2.3"/>
      <inertia ixx="0.0143" ixy="0.0" ixz="0.0" iyy="0.0055" iyz="0.0" izz="0.015"/>
    </inertial>
  </link>
  <link name="Link_1_1">
    <visual>
      <origin rpy="0 0 0" xyz="-0.0 -0.000 -0.1126"/>
      <geometry>
        <mesh filename="package://arctos_description/meshes/Link_1_1.stl" scale="0.001 0.001 0.001"/>
      </geometry>
      <material name="white"/>
    </visual>
    <collision>
      <origin rpy="0 0 0" xyz="-0.0 -0.000 -0.1126"/>
      <geometry>
        <mesh filename="package://arctos_description/meshes/Link_1_1.stl" scale="0.001 0.001 0.001"/>
      </geometry>
    </collision>
    <inertial>
      <origin rpy="0 0 0" xyz="-0.0088 -0.0005 0.099"/>
      <mass value="3.0396"/>
      <inertia ixx="0.0143" ixy="-0.0005657079999999999" ixz="-0.0016510779999999998" iyy="0.016218048" iyz="0.004233264" izz="0.008070888"/>
    </inertial>
  </link>
  <link name="Link_2_1">
    <visual>
      <origin rpy="0 0 0" xyz="0.0 0.020356 -0.2876"/>
      <geometry>
        <mesh filename="package://arctos_description/meshes/Link_2_1.stl" scale="0.001 0.001 0.001"/>
      </geometry>
      <material name="white"/>
    </visual>
    <collision>
      <origin rpy="0 0 0" xyz="0.0 0.020356 -0.2876"/>
      <geometry>
        <mesh filename="package://arctos_description/meshes/Link_2_1.stl" scale="0.001 0.001 0.001"/>
      </geometry>
    </collision>
    <inertial>
      <origin rpy="0 0 0" xyz="0.0042 0.010556 0.12979999999999997"/>
      <mass value="2.527"/>
      <inertia ixx="0.028157981999999998" ixy="0.001451172" ixz="-0.000511266" iyy="0.0299595" iyz="-0.0001773" izz="0.006298866"/>
    </inertial>
  </link>
  <link name="Link_3_1">
    <visual>
      <origin rpy="0 0 0" xyz="-0.0 0.019045 -0.54864"/>
      <geometry>
        <mesh filename="package://arctos_description/meshes/Link_3_1.stl" scale="0.001 0.001 0.001"/>
      </geometry>
      <material name="white"/>
    </visual>
    <collision>
      <origin rpy="0 0 0" xyz="-0.0 0.019045 -0.54864"/>
      <geometry>
        <mesh filename="package://arctos_description/meshes/Link_3_1.stl" scale="0.001 0.001 0.001"/>
      </geometry>
    </collision>
    <inertial>
      <origin rpy="0 0 0" xyz="0.00158 -0.053 0.009"/>
      <mass value="0.87"/>
      <inertia ixx="0.002798432" ixy="-6.1684e-05" ixz="7.019599999999999e-05" iyy="0.001082686" iyz="-0.00017481" izz="0.002657556"/>
    </inertial>
  </link>
  <link name="Link_4_1">
    <visual>
      <origin rpy="0 0 0" xyz="0.0 0.1578 -0.5704"/>
      <geometry>
        <mesh filename="package://arctos_description/meshes/Link_4_1.stl" scale="0.001 0.001 0.001"/>
      </geometry>
      <material name="white"/>
    </visual>
    <collision>
      <origin rpy="0 0 0" xyz="0.0 0.1578 -0.5704"/>
      <geometry>
        <mesh filename="package://arctos_description/meshes/Link_4_1.stl" scale="0.001 0.001 0.001"/>
      </geometry>
    </collision>
    <inertial>
      <origin rpy="0 0 0" xyz="0.0 -0.0535 -0.001733"/>
      <mass value="1.006"/>
      <inertia ixx="0.002094246" ixy="-0.0013240499999999998" ixz="8.1102e-05" iyy="0.0023952239999999996" iyz="1.9679999999999996e-06" izz="0.0031976"/>
    </inertial>
  </link>
  <link name="Link_5_1">
    <visual>
      <origin rpy="0 0 0" xyz="0.0 0.2832 -0.56856"/>
      <geometry>
        <mesh filename="package://arctos_description/meshes/Link_5_1.stl" scale="0.001 0.001 0.001"/>
      </geometry>
      <material name="white"/>
    </visual>
    <collision>
      <origin rpy="0 0 0" xyz="0.0 0.2832 -0.56856"/>
      <geometry>
        <mesh filename="package://arctos_description/meshes/Link_5_1.stl" scale="0.001 0.001 0.001"/>
      </geometry>
    </collision>
    <inertial>
      <origin rpy="0 0 0" xyz="-0.0007 -0.0142 -0.0008"/>
      <mass value="0.3344"/>
      <inertia ixx="0.0002" ixy="0.0" ixz="0.0" iyy="0.0005" iyz="0.0" izz="0.0005"/>
    </inertial>
  </link>
  <link name="Link_6_1">
    <visual>
      <origin rpy="0 0 0" xyz="0.0 0.323 -0.5685"/>
      <geometry>
        <mesh filename="package://arctos_description/meshes/Link_6_1.stl" scale="0.001 0.001 0.001"/>
      </geometry>
      <material name="white"/>
    </visual>
    <collision>
      <origin rpy="0 0 0" xyz="0.0 0.323 -0.5685"/>
      <geometry>
        <mesh filename="package://arctos_description/meshes/Link_6_1.stl" scale="0.001 0.001 0.001"/>
      </geometry>
    </collision>
    <inertial>
      <origin rpy="0 0 0" xyz="-0.0 -0.0 0.0"/>
      <mass value="0.001"/>
      <inertia ixx="0.001" ixy="-0.0" ixz="0.0" iyy="0.001" iyz="0.0" izz="0.001"/>
    </inertial>
  </link>
  <!-- World fixed joint -->
  <link name="world"/>
  <joint name="world_joint" type="fixed">
    <parent link="world"/>
    <child link="base_link"/>
  </joint>
  <joint name="X_joint" type="revolute">
    <parent link="base_link"/>
    <child link="Link_1_1"/>
    <origin rpy="0 0 0" xyz="0 0 0.1126"/>
    <axis xyz="0 0 1"/>
    <limit effort="24.3" lower="-3.141592653589793" upper="3.141592653589793" velocity="23.271057"/>
  </joint>
  <joint name="Y_joint" type="revolute">
    <parent link="Link_1_1"/>
    <child link="Link_2_1"/>
    <origin rpy="0 0 0" xyz="0 -0.020356 0.17500000000000002"/>
    <axis xyz="1 0 0"/>
    <limit effort="270" lower="-0.96" upper="2.18" velocity="2.094395"/>
  </joint>
  <joint name="Z_joint" type="revolute">
    <parent link="Link_2_1"/>
    <child link="Link_3_1"/>
    <origin rpy="0 0 0" xyz="0 0.001365 0.261035"/>
    <axis xyz="1 0 0"/>
    <limit effort="97" lower="-1.5707963267948966" upper="1.2217304763960306" velocity="2.094395"/>
  </joint>
  <joint name="A_joint" type="revolute">
    <parent link="Link_3_1"/>
    <child link="Link_4_1"/>
    <origin rpy="0 0 0" xyz="0 -0.13881 0.0217651"/>
    <axis xyz="0 1 0"/>
    <limit effort="22" lower="-3.141592653589793" upper="3.141592653589793" velocity="6.544985"/>
  </joint>
  <joint name="B_joint" type="revolute">
    <parent link="Link_4_1"/>
    <child link="Link_5_1"/>
    <origin rpy="0 0 0" xyz="0 -0.12543 -0.00184"/>
    <axis xyz="-1 0 0"/>
    <limit effort="16" lower="-1.55" upper="1.55" velocity="11.49188"/>
  </joint>
  <joint name="C_joint" type="revolute">
    <parent link="Link_5_1"/>
    <child link="Link_6_1"/>
    <origin rpy="0 0 0" xyz="0 -0.0398 0"/>
    <axis xyz="0 1 0"/>
    <limit effort="16" lower="-3.141592653589793" upper="3.141592653589793" velocity="31.415927"/>
  </joint>
  <link name="Gripper_1">
    <visual>
      <origin rpy="0 0 0" xyz="0 0.323 -0.5685"/>
      <geometry>
        <mesh filename="package://arctos_description/meshes/Gripper_1.stl" scale="0.001 0.001 0.001"/>
      </geometry>
      <material name="white"/>
    </visual>
    <collision>
      <origin rpy="0 0 0" xyz="0 0.323 -0.5685"/>
      <geometry>
        <mesh filename="package://arctos_description/meshes/Gripper_1.stl" scale="0.001 0.001 0.001"/>
      </geometry>
    </collision>
    <inertial>
      <origin rpy="0 0 0" xyz="-0.001 -0.0211 0"/>
      <mass value="0.2"/>
      <inertia ixx="0.0001" ixy="0" ixz="0" iyy="0.0001" iyz="0" izz="0.0001"/>
    </inertial>
  </link>
  <link name="Left_jaw_1">
    <visual>
      <origin rpy="0 0 0" xyz="0 0.323 -0.5685"/>
      <geometry>
        <mesh filename="package://arctos_description/meshes/Left_jaw_1.stl" scale="0.001 0.001 0.001"/>
      </geometry>
      <material name="white"/>
    </visual>
    <collision>
      <origin rpy="0 0 0" xyz="0 0.323 -0.5685"/>
      <geometry>
        <mesh filename="package://arctos_description/meshes/Left_jaw_1.stl" scale="0.001 0.001 0.001"/>
      </geometry>
    </collision>
    <inertial>
      <origin rpy="0 0 0" xyz="0 -0.0211 0"/>
      <mass value="0.01"/>
      <inertia ixx="1e-05" ixy="0" ixz="0" iyy="1e-05" iyz="0" izz="1e-05"/>
    </inertial>
  </link>
  <link name="Right_jaw_1">
    <visual>
      <origin rpy="0 0 0" xyz="0 0.323 -0.5685"/>
      <geometry>
        <mesh filename="package://arctos_description/meshes/Right_jaw_1.stl" scale="0.001 0.001 0.001"/>
      </geometry>
      <material name="white"/>
    </visual>
    <collision>
      <origin rpy="0 0 0" xyz="0 0.323 -0.5685"/>
      <geometry>
        <mesh filename="package://arctos_description/meshes/Right_jaw_1.stl" scale="0.001 0.001 0.001"/>
      </geometry>
    </collision>
    <inertial>
      <origin rpy="0 0 0" xyz="-0.001 -0.0211 0"/>
      <mass value="0.01"/>
      <inertia ixx="1e-05" ixy="0" ixz="0" iyy="1e-05" iyz="0" izz="1e-05"/>
    </inertial>
  </link>
  <joint name="Gripper_joint" type="fixed">
    <parent link="Link_6_1"/>
    <child link="Gripper_1"/>
    <origin rpy="0 0 0" xyz="0 0 0"/>
    <axis xyz="0 0 1"/>
    <limit effort="0" lower="0" upper="0" velocity="0"/>
  </joint>
  <joint name="Left_jaw_joint" type="fixed">
    <parent link="Gripper_1"/>
    <child link="Left_jaw_1"/>
    <origin rpy="0 0 0" xyz="0 0 0"/>
    <axis xyz="0 0 -1"/>
    <limit effort="1" lower="0" upper="0.015" velocity="10"/>
  </joint>
  <joint name="Right_jaw_joint" type="fixed">
    <parent link="Gripper_1"/>
    <child link="Right_jaw_1"/>
    <origin rpy="0 0 0" xyz="0 0 0"/>
    <axis xyz="0 0 1"/>
    <limit effort="1" lower="0" upper="0.015" velocity="10"/>
  </joint>
  <ros2_control name="arctos_interface" type="system">
    <hardware>
      <plugin>topic_based_ros2_control/TopicBasedSystem</plugin>
      <param name="joint_commands_topic">/joint_commands_radian</param>
      <param name="joint_states_topic">/topic_based_joint_states</param>
      <param name="sum_wrapped_joint_states">true</param>
    </hardware>
    <joint name="X_joint">
      <command_interface name="position">
        <param name="min">-3.141592653589793</param>
        <param name="max">3.141592653589793</param>
      </command_interface>
      <command_interface name="velocity"/>
      <state_interface name="position"/>
      <state_interface name="velocity"/>
    </joint>
    <joint name="Y_joint">
      <command_interface name="position">
        <param name="min">1.97</param>
        <param name="max">-0.88</param>
      </command_interface>
      <command_interface name="velocity"/>
      <state_interface name="position"/>
      <state_interface name="velocity"/>
    </joint>
    <joint name="Z_joint">
      <command_interface name="position">
        <param name="min">-1.6</param>
        <param name="max">0.65</param>
      </command_interface>
      <command_interface name="velocity"/>
      <state_interface name="position"/>
      <state_interface name="velocity"/>
    </joint>
    <joint name="A_joint">
      <command_interface name="position">
        <param name="min">-3.141592653589793</param>
        <param name="max">3.141592653589793</param>
      </command_interface>
      <command_interface name="velocity"/>
      <state_interface name="position"/>
      <state_interface name="velocity"/>
    </joint>
    <joint name="B_joint">
      <command_interface name="position">
        <param name="min">-1.55</param>
        <param name="max">1.55</param>
      </command_interface>
      <command_interface name="velocity"/>
      <state_interface name="position"/>
      <state_interface name="velocity"/>
    </joint>
    <joint name="C_joint">
      <command_interface name="position">
        <param name="min">-3.141592653589793</param>
        <param name="max">3.141592653589793</param>
      </command_interface>
      <command_interface name="velocity"/>
      <state_interface name="position"/>
      <state_interface name="velocity"/>
    </joint>
  </ros2_control>
</robot>
